import {
  WorkflowClient,
  WorkflowHandle,
  WorkflowExecutionFailedError,
  ActivityFailure,
  ApplicationFailure,
} from '@temporalio/client';
import { Core, Worker, DefaultLogger } from '@temporalio/worker';
import { describe, before, after, afterEach, it } from 'mocha';
import assert from 'assert';
import axios from 'axios';
import sinon from 'sinon';
import { httpWorkflow } from '../workflows';
import * as activities from '../activities';

describe('example workflow', function () {
  let shutdown: () => Promise<void>;
  let workflow: WorkflowHandle<typeof httpWorkflow>;

  this.slow(1000);

  before(async function () {
    this.timeout(10 * 1000);
    // Filter INFO log messages for clearer test output
    await Core.install({ logger: new DefaultLogger('WARN') });
    const worker = await Worker.create({
      taskQueue: 'test-activities',
      workflowsPath: require.resolve('../workflows'),
      activities,
    });

    const runPromise = worker.run();
    shutdown = async () => {
      worker.shutdown();
      await runPromise;
    };
  });

  beforeEach(() => {
    const client = new WorkflowClient();

    workflow = client.createWorkflowHandle(httpWorkflow, {
      taskQueue: 'test-activities',
      workflowExecutionTimeout: 1000,
    });
  });

  after(async () => {
    await shutdown();
  });

  afterEach(() => {
    sinon.restore();
  });

  it('returns correct result', async () => {
    const result = await workflow.execute();
    assert.equal(result, 'The answer is 42');
  });

  it('retries one failure', async () => {
    // Make the first request fail, but subsequent requests succeed
    let numCalls = 0;
    sinon.stub(axios, 'get').callsFake(() => {
      if (numCalls++ === 0) {
        return Promise.reject(new Error('first error'));
      }
      return Promise.resolve({ data: { args: { answer: '88' } } });
    });

    const result = await workflow.execute();
    assert.equal(result, 'The answer is 88');
  });

  it('bubbles up activity errors', async () => {
    sinon.stub(axios, 'get').callsFake(() => Promise.reject(new Error('example error')));

    await assert.rejects(
      () => workflow.execute(),
      (err: unknown) =>
        err instanceof WorkflowExecutionFailedError &&
        err.cause instanceof ActivityFailure &&
        err.cause.cause instanceof ApplicationFailure &&
        err.cause.cause.message === 'example error'
    );
  });
});
